Workbook

Sheet Instrucciones
A1: Cómo usar esta matriz
A2: 1. Trabaja en la hoja 'Casos'. Actualiza Estado (lista desplegable), Resultado real, Fecha, Ejecutor y Evidencia.
A3: 2. La hoja 'Resumen' se recalcula sola (fórmulas COUNTIFS).
A4: 3. Tipo: A = automatizado con pytest, S = semi-automático (script/simulador), M = manual.
A5: 4. Un caso 'Falló' debe tener evidencia (captura del monitor serie, log de la API o consulta SQL).
A6: 5. La fuente de los casos es scripts/casos_de_prueba.py; si cambias el plan, regenera con generar_documentos.py.

Sheet Casos
A1: ID | B1: Nivel | C1: Componente | D1: Título | E1: Requisito | F1: Prioridad | G1: Tipo | H1: Precondiciones | I1: Pasos | J1: Datos de prueba | K1: Resultado esperado | L1: Automatización / referencia | M1: Estado | N1: Resultado real | O1: Fecha | P1: Ejecutor | Q1: Evidencia (captura/log)
A2: IT-ENV-01 | B2: N0 | C2: Entorno AWS y Docker | D2: Acceso SSH a la EC2 y versión de Python | E2: RNF-02 | F2: Alta | G2: M | H2: Laboratorio iniciado; EC2 en ejecución. | I2: 1. ssh -i labsuser.pem ec2-user@<IP> 2. python3 --version | J2: IP pública / Elastic IP | K2: Acceso correcto; Python ≥ 3.11 disponible. | M2: Pendiente
A3: IT-ENV-02 | B3: N0 | C3: Entorno AWS y Docker | D3: Puerto de la API alcanzable desde la red del ESP32 | E3: RF-03 | F3: Alta | G3: M | H3: SG `sg-api` con regla de entrada TCP 8000; API en ejecución. | I3: 1. Desde un celular con datos móviles y desde el WiFi del ESP32: abrir http://<IP>:8000/health | J3: URL /health | K3: Responde 200 con {"status":"ok","db":"ok"} desde ambas redes. | M3: Pendiente
A4: IT-ENV-03 | B4: N0 | C4: Entorno AWS y Docker | D4: Stack docker compose sano y PostgreSQL sin puertos publicados | E4: RNF-03 | F4: Alta | G4: M | H4: EC2 con Docker; `deploy/.env` creado. | I4: 1. En la EC2: cd deploy && docker compose up -d --build 2. docker compose ps (todos healthy) 3. docker compose exec db psql -U sensores_app -d sensores -c 'SELECT 1' 4. docker compose port db 5432 | J4: deploy/docker-compose.yml | K4: api y db en estado healthy; `SELECT 1` devuelve 1; `docker compose port db 5432` no devuelve ningún puerto publicado. | M4: Pendiente
A5: IT-ENV-04 | B5: N0 | C5: Entorno AWS y Docker | D5: Esquema aplicado con restricciones | E5: RF-04 | F5: Alta | G5: M | H5: Contenedor `db` iniciado con el volumen vacío (aplica `db/schema.sql` al inicializar). | I5: 1. docker compose exec db psql -U sensores_app -d sensores 2. En psql: \d lectura 3. Verificar UNIQUE (dispositivo_id, seq) y FKs con ON DELETE CASCADE 4. Verificar que existe el rol grafana_ro con solo SELECT | J5: db/schema.sql · db/02-roles.sh | K5: Existen dispositivo, lectura y medicion con índices y restricciones. | M5: Pendiente
A6: IT-ENV-05 | B6: N0 | C6: Entorno AWS y Docker | D6: Contenedores con política de reinicio | E6: RNF-02 | F6: Media | G6: M | H6: Stack en ejecución. | I6: 1. docker inspect -f '{{.HostConfig.RestartPolicy.Name}}' nextguard-api-1 nextguard-db-1 nextguard-grafana-1 2. curl localhost:8000/health | J6: — | K6: Los tres contenedores usan `unless-stopped`; /health = 200. | M6: Pendiente
A7: IT-ENV-06 | B7: N0 | C7: Entorno AWS y Docker | D7: Prueba de humo del entorno | E7: RNF-02 | F7: Alta | G7: S | H7: Stack docker compose operativo. | I7: 1. En la EC2: API_URL=http://localhost:8000 API_KEY=... GRAFANA_URL=http://localhost:3000 ./scripts/smoke_env.sh | J7: smoke_env.sh | K7: Todas las verificaciones [OK], código de salida 0. | L7: scripts/smoke_env.sh | M7: Pendiente
A8: IT-ENV-07 | B8: N0 | C8: Entorno AWS y Docker | D8: Grafana con datasource y dashboard aprovisionados | E8: RF-08 | F8: Alta | G8: S | H8: Stack en ejecución; lecturas enviadas con el simulador. | I8: 1. Abrir http://<IP>:3000 e iniciar sesión con el usuario de .env 2. Connections → Data sources → NextGuard → Save & test 3. Abrir el dashboard «NextGuard · Monitoreo IoT» | J8: deploy/grafana/ | K8: El datasource responde «Database Connection OK»; los paneles de temperatura, humedad y lecturas por minuto muestran las lecturas del simulador. | M8: Pendiente
A9: IT-ENV-08 | B9: N0 | C9: Entorno AWS y Docker | D9: Persistencia de datos tras bajar y subir el stack | E9: RNF-02 | F9: Alta | G9: S | H9: Lecturas cargadas en la BD. | I9: 1. docker compose down (sin -v) 2. docker compose up -d 3. GET /api/v1/lecturas y abrir el dashboard | J9: — | K9: Las lecturas y el dashboard siguen disponibles; la API reconecta sola a la BD. | M9: Pendiente
A10: IT-SEN-01 | B10: N1 | C10: Sensor ↔ ESP32 | D10: Lectura DHT válida y dentro de rango | E10: RF-01 | F10: Alta | G10: M | H10: USE_DHT=1; DHT cableado (VCC, GND, DATA con pull-up); monitor serie a 115200. | I10: 1. Cargar firmware 2. Observar 10 muestras en el monitor serie 3. Comparar con un termómetro/higrómetro de referencia | J10: DHT11 o DHT22 | K10: T entre -40 y 80 °C y H entre 0 y 100 %; diferencia con la referencia dentro de la tolerancia del sensor (DHT22 ±0,5 °C; DHT11 ±2 °C). | M10: Pendiente
A11: IT-SEN-02 | B11: N1 | C11: Sensor ↔ ESP32 | D11: Lectura inválida (NaN) no se envía y el sistema sigue | E11: RF-05 | F11: Alta | G11: M | H11: Firmware ejecutándose con DHT real. | I11: 1. Desconectar el pin DATA durante 30 s 2. Reconectarlo | J11: — | K11: Se imprime '[SENSOR] lectura inválida' y no se encola nada; al reconectar se retoman las lecturas sin reiniciar. | M11: Pendiente
A12: IT-SEN-03 | B12: N1 | C12: Sensor ↔ ESP32 | D12: Frecuencia de muestreo | E12: RF-01 | F12: Media | G12: M | H12: Firmware ejecutándose. | I12: 1. Registrar durante 5 min las marcas de tiempo de [MUESTRA] 2. Calcular el periodo medio | J12: INTERVALO_MS = 10000 | K12: Periodo medio 10 s ±5 %; sin ráfagas ni huecos. | M12: Pendiente
A13: IT-SEN-04 | B13: N1 | C13: Sensor ↔ ESP32 | D13: Respuesta a un cambio físico | E13: RF-01 | F13: Media | G13: M | H13: Firmware ejecutándose y llegando datos a la BD. | I13: 1. Exhalar sobre el sensor 5 s 2. Consultar las últimas lecturas por API | J13: — | K13: La humedad sube de forma visible y el cambio aparece en la BD. | M13: Pendiente
A14: IT-SEN-05 | B14: N1 | C14: Sensor ↔ ESP32 | D14: Modo simulado sin hardware | E14: RF-01 | F14: Baja | G14: M | H14: USE_DHT=0. | I14: 1. Cargar firmware 2. Observar 20 muestras | J14: — | K14: Valores plausibles (T ≈ 22 °C variando ≤ 0,3 °C por muestra; H entre 0 y 100 %). | M14: Pendiente
A15: IT-NET-01 | B15: N2 | C15: ESP32 ↔ Red WiFi / NTP | D15: Conexión WiFi inicial e IP | E15: RF-02 | F15: Alta | G15: M | H15: Red 2.4 GHz con WPA2; config.h correcto. | I15: 1. Encender el ESP32 2. Observar el monitor serie | J15: SSID/clave | K15: Se imprime la IP asignada en menos de 20 s. | L15: wifi_diagnostico.ino | M15: Pendiente
A16: IT-NET-02 | B16: N2 | C16: ESP32 ↔ Red WiFi / NTP | D16: Clave WiFi incorrecta: motivo registrado y sin bloqueo | E16: RF-02 | F16: Media | G16: M | H16: config.h con clave errónea. | I16: 1. Cargar firmware 2. Observar 2 min | J16: Clave inválida | K16: Se registra el motivo de desconexión; el muestreo continúa y las muestras se encolan (sin cuelgue ni reinicio). | M16: Pendiente
A17: IT-NET-03 | B17: N2 | C17: ESP32 ↔ Red WiFi / NTP | D17: Caída del router durante la ejecución | E17: RF-02 | F17: Alta | G17: M | H17: ESP32 enviando con normalidad. | I17: 1. Apagar el router 2 min 2. Encenderlo 3. Esperar 3 min | J17: — | K17: El ESP32 se reconecta solo; las muestras acumuladas se entregan (sin faltas ni duplicados). | M17: Pendiente
A18: IT-NET-04 | B18: N2 | C18: ESP32 ↔ Red WiFi / NTP | D18: Hora NTP y campo ts_dispositivo | E18: RNF-04 | F18: Media | G18: M | H18: Internet disponible. | I18: 1. Arrancar y revisar '[MUESTRA] … hora=NTP' 2. Consultar la API y ver ts_dispositivo 3. Repetir con Internet bloqueado en el router | J18: — | K18: Con NTP: ts_dispositivo en UTC correcto. Sin NTP: ts_dispositivo = null y la lectura se guarda igual. | M18: Pendiente
A19: IT-NET-05 | B19: N2 | C19: ESP32 ↔ Red WiFi / NTP | D19: Entrega según intensidad de señal | E19: RNF-02 | F19: Baja | G19: M | H19: Dispositivo alimentado por batería/USB estable. | I19: 1. Medir 10 min a tres distancias (RSSI ≈ -50, -70, -80 dBm) 2. Comparar enviadas vs guardadas | J19: RSSI | K19: Entrega ≥ 99 % con RSSI ≥ -80 dBm. | M19: Pendiente
A20: IT-API-01 | B20: N2 | C20: ESP32 ↔ API (contrato HTTP) | D20: Crear lectura válida → 201 | E20: RF-04 | F20: Alta | G20: A | H20: API con API key válida. | I20: 1. POST /api/v1/lecturas con payload válido | J20: payload estándar | K20: 201 y {duplicado:false}. | L20: tests/test_api_contrato.py::test_it_api_01 | M20: Pendiente
A21: IT-API-02 | B21: N2 | C21: ESP32 ↔ API (contrato HTTP) | D21: Reintento con el mismo seq → 200 idempotente | E21: RF-05 | F21: Alta | G21: A | H21: Lectura seq=7 ya guardada. | I21: 1. Reenviar la misma lectura | J21: seq=7 | K21: 200 con {duplicado:true}; sigue habiendo 1 sola fila. | L21: tests/test_api_contrato.py::test_it_api_02 | M21: Pendiente
A22: IT-API-03 | B22: N2 | C22: ESP32 ↔ API (contrato HTTP) | D22: Sin API key → 401 | E22: RNF-03 | F22: Alta | G22: A | H22: — | I22: 1. POST sin cabecera X-API-Key | J22: — | K22: 401 y no se guarda nada. | L22: tests/test_api_contrato.py::test_it_api_03 | M22: Pendiente
A23: IT-API-04 | B23: N2 | C23: ESP32 ↔ API (contrato HTTP) | D23: API key incorrecta → 401 | E23: RNF-03 | F23: Alta | G23: A | H23: — | I23: 1. POST con X-API-Key errónea | J23: — | K23: 401. | L23: tests/test_api_contrato.py::test_it_api_04 | M23: Pendiente
A24: IT-API-05 | B24: N2 | C24: ESP32 ↔ API (contrato HTTP) | D24: Lectura sin mediciones → 422 | E24: RF-04 | F24: Media | G24: A | H24: — | I24: 1. POST con mediciones=[] | J24: — | K24: 422. | L24: tests/test_api_contrato.py::test_it_api_05 | M24: Pendiente
A25: IT-API-06 | B25: N2 | C25: ESP32 ↔ API (contrato HTTP) | D25: device_id con caracteres inválidos → 422 | E25: RNF-03 | F25: Media | G25: A | H25: — | I25: 1. POST con device_id='esp 01;' | J25: — | K25: 422. | L25: tests/test_api_contrato.py::test_it_api_06 | M25: Pendiente
A26: IT-API-07 | B26: N2 | C26: ESP32 ↔ API (contrato HTTP) | D26: Valor NaN → 422 (no 500) | E26: RF-04 | F26: Alta | G26: A | H26: — | I26: 1. POST con "valor": NaN (JSON no estándar) | J26: — | K26: 422 con detalle sin el valor recibido; la API no falla con 500. | L26: tests/test_api_contrato.py::test_it_api_07 | M26: Pendiente
A27: IT-API-08 | B27: N2 | C27: ESP32 ↔ API (contrato HTTP) | D27: JSON malformado → 422 | E27: RF-04 | F27: Media | G27: A | H27: — | I27: 1. POST con cuerpo '{no es json' | J27: — | K27: 422. | L27: tests/test_api_contrato.py::test_it_api_08 | M27: Pendiente
A28: IT-API-09 | B28: N2 | C28: ESP32 ↔ API (contrato HTTP) | D28: Payload demasiado grande → 413 | E28: RNF-03 | F28: Media | G28: A | H28: MAX_BODY_BYTES configurado. | I28: 1. POST con cuerpo mayor al límite | J28: ≥ 5 KB en pruebas | K28: 413. | L28: tests/test_api_contrato.py::test_it_api_09 | M28: Pendiente
A29: IT-API-10 | B29: N2 | C29: ESP32 ↔ API (contrato HTTP) | D29: Campo desconocido → 422 | E29: RF-04 | F29: Baja | G29: A | H29: — | I29: 1. POST con un campo extra | J29: — | K29: 422 (esquema estricto). | L29: tests/test_api_contrato.py::test_it_api_10 | M29: Pendiente
A30: IT-API-11 | B30: N2 | C30: ESP32 ↔ API (contrato HTTP) | D30: Sin ts_dispositivo se acepta | E30: RNF-04 | F30: Media | G30: A | H30: — | I30: 1. POST sin ts_dispositivo 2. GET de la lectura | J30: — | K30: 201; ts_dispositivo = null. | L30: tests/test_api_contrato.py::test_it_api_11 | M30: Pendiente
A31: IT-API-12 | B31: N2 | C31: ESP32 ↔ API (contrato HTTP) | D31: Lote con nuevas y duplicadas | E31: RF-05 | F31: Alta | G31: A | H31: seq=1 ya guardado. | I31: 1. POST /batch con seq 1, 2, 3 | J31: 3 lecturas | K31: {insertadas:2, duplicadas:1}. | L31: tests/test_api_contrato.py::test_it_api_12 | M31: Pendiente
... A36: IT-API-17 | B36: N2 | C36: ESP32 ↔ API (contrato HTTP) | D36: /health sin clave y refleja la BD | E36: RNF-02 | F36: Media | G36: A | H36: — | I36: 1. GET /health | J36: — | K36: 200 {status:ok, db:ok}. | L36: tests/test_api_contrato.py::test_it_api_17 | M36: Pendiente
A37: IT-API-18 | B37: N2 | C37: ESP32 ↔ API (contrato HTTP) | D37: ESP32 real: primer envío correcto | E37: RF-03 | F37: Alta | G37: M | H37: API accesible; config.h con API_HOST y API_KEY correctos. | I37: 1. Encender el ESP32 2. Esperar la primera muestra 3. Ver el monitor serie | J37: — | K37: Se imprime '[API] 201 OK' y la lectura aparece en GET /api/v1/lecturas. | M37: Pendiente
A38: IT-API-19 | B38: N2 | C38: ESP32 ↔ API (contrato HTTP) | D38: ESP32 con API key errónea: 401, backoff y sin pérdida | E38: RF-05 | F38: Media | G38: M | H38: config.h con API_KEY incorrecta. | I38: 1. Encender 3 min 2. Corregir API_KEY y volver a cargar | J38: — | K38: Se registra 'fallo 401' con espera creciente (2, 4, 8… hasta 60 s); las muestras se conservan en la cola mientras no se llene. | M38: Pendiente
A39: IT-API-20 | B39: N2 | C39: ESP32 ↔ API (contrato HTTP) | D39: API caída 3 min: la cola se vacía al recuperar | E39: RF-05 | F39: Alta | G39: M | H39: ESP32 enviando con normalidad. | I39: 1. sudo systemctl stop sensores-api (3 min) 2. sudo systemctl start sensores-api 3. Comparar seq del monitor serie vs BD | J39: — | K39: Sin faltas ni duplicados; se usan envíos por lote para vaciar la cola; el orden se conserva. | M39: Pendiente
A40: IT-API-21 | B40: N2 | C40: ESP32 ↔ API (contrato HTTP) | D40: Timeout de red: el ESP32 no se bloquea | E40: RNF-02 | F40: Media | G40: M | H40: ESP32 enviando con normalidad. | I40: 1. Quitar la regla del SG que permite el puerto 8000 (los paquetes se descartan) 2. Observar 2 min 3. Restaurar la regla | J40: — | K40: Cada intento termina por timeout (≈5 s), el muestreo sigue a su ritmo y al restaurar se entrega todo. | M40: Pendiente
A41: IT-DB-01 | B41: N3 | C41: API ↔ Base de datos | D41: Inserta dispositivo, lectura y mediciones | E41: RF-04 | F41: Alta | G41: A | H41: BD vacía. | I41: 1. POST de una lectura con 2 mediciones 2. Contar filas | J41: ubicación='Laboratorio 2' | K41: 1 dispositivo, 1 lectura, 2 mediciones. | L41: tests/test_bd.py::test_it_db_01 | M41: Pendiente
A42: IT-DB-02 | B42: N3 | C42: API ↔ Base de datos | D42: UNIQUE (dispositivo_id, seq) a nivel de BD | E42: RF-05 | F42: Alta | G42: A | H42: Lectura seq=1 guardada. | I42: 1. Insertar otra fila con el mismo dispositivo y seq directamente en la BD | J42: — | K42: IntegrityError (la BD protege contra duplicados aunque falle la API). | L42: tests/test_bd.py::test_it_db_02 | M42: Pendiente
A43: IT-DB-03 | B43: N3 | C43: API ↔ Base de datos | D43: Mismo seq en dispositivos distintos es válido | E43: RF-05 | F43: Media | G43: A | H43: — | I43: 1. POST seq=1 para esp32-01 y esp32-02 | J43: — | K43: Ambos 201. | L43: tests/test_bd.py::test_it_db_03 | M43: Pendiente
A44: IT-DB-04 | B44: N3 | C44: API ↔ Base de datos | D44: Nueva magnitud sin cambiar el esquema | E44: RF-07 | F44: Alta | G44: A | H44: — | I44: 1. POST con pm2_5 y pm10 además de T/H 2. GET | J44: pm2_5=12.5; pm10=20.1 | K44: Las 4 magnitudes se guardan y se consultan. | L44: tests/test_bd.py::test_it_db_04 | M44: Pendiente
...

Sheet Resumen
A1: Nivel | B1: Componente | C1: Total | D1: Pendiente | E1: En curso | F1: Pasó | G1: Falló | H1: Bloqueado | I1: No aplica | J1: % Pasó
A2: N0 | B2: Entorno AWS y Docker | C2: =COUNTIF(Casos!$B$2:$B$76,A2) | D2: =COUNTIFS(Casos!$B$2:$B$76,$A2,Casos!$M$2:$M$76,D$1) | E2: =COUNTIFS(Casos!$B$2:$B$76,$A2,Casos!$M$2:$M$76,E$1) | F2: =COUNTIFS(Casos!$B$2:$B$76,$A2,Casos!$M$2:$M$76,F$1) | G2: =COUNTIFS(Casos!$B$2:$B$76,$A2,Casos!$M$2:$M$76,G$1) | H2: =COUNTIFS(Casos!$B$2:$B$76,$A2,Casos!$M$2:$M$76,H$1) | I2: =COUNTIFS(Casos!$B$2:$B$76,$A2,Casos!$M$2:$M$76,I$1) | J2: =IF(C2=0,0,F2/C2)
A3: N1 | B3: Sensor ↔ ESP32 | C3: =COUNTIF(Casos!$B$2:$B$76,A3) | D3: =COUNTIFS(Casos!$B$2:$B$76,$A3,Casos!$M$2:$M$76,D$1) | E3: =COUNTIFS(Casos!$B$2:$B$76,$A3,Casos!$M$2:$M$76,E$1) | F3: =COUNTIFS(Casos!$B$2:$B$76,$A3,Casos!$M$2:$M$76,F$1) | G3: =COUNTIFS(Casos!$B$2:$B$76,$A3,Casos!$M$2:$M$76,G$1) | H3: =COUNTIFS(Casos!$B$2:$B$76,$A3,Casos!$M$2:$M$76,H$1) | I3: =COUNTIFS(Casos!$B$2:$B$76,$A3,Casos!$M$2:$M$76,I$1) | J3: =IF(C3=0,0,F3/C3)
A4: N2 | B4: ESP32 ↔ Red WiFi / NTP / ESP32 ↔ API (contrato HTTP) | C4: =COUNTIF(Casos!$B$2:$B$76,A4) | D4: =COUNTIFS(Casos!$B$2:$B$76,$A4,Casos!$M$2:$M$76,D$1) | E4: =COUNTIFS(Casos!$B$2:$B$76,$A4,Casos!$M$2:$M$76,E$1) | F4: =COUNTIFS(Casos!$B$2:$B$76,$A4,Casos!$M$2:$M$76,F$1) | G4: =COUNTIFS(Casos!$B$2:$B$76,$A4,Casos!$M$2:$M$76,G$1) | H4: =COUNTIFS(Casos!$B$2:$B$76,$A4,Casos!$M$2:$M$76,H$1) | I4: =COUNTIFS(Casos!$B$2:$B$76,$A4,Casos!$M$2:$M$76,I$1) | J4: =IF(C4=0,0,F4/C4)
A5: N3 | B5: API ↔ Base de datos | C5: =COUNTIF(Casos!$B$2:$B$76,A5) | D5: =COUNTIFS(Casos!$B$2:$B$76,$A5,Casos!$M$2:$M$76,D$1) | E5: =COUNTIFS(Casos!$B$2:$B$76,$A5,Casos!$M$2:$M$76,E$1) | F5: =COUNTIFS(Casos!$B$2:$B$76,$A5,Casos!$M$2:$M$76,F$1) | G5: =COUNTIFS(Casos!$B$2:$B$76,$A5,Casos!$M$2:$M$76,G$1) | H5: =COUNTIFS(Casos!$B$2:$B$76,$A5,Casos!$M$2:$M$76,H$1) | I5: =COUNTIFS(Casos!$B$2:$B$76,$A5,Casos!$M$2:$M$76,I$1) | J5: =IF(C5=0,0,F5/C5)
A6: N4 | B6: Extremo a extremo | C6: =COUNTIF(Casos!$B$2:$B$76,A6) | D6: =COUNTIFS(Casos!$B$2:$B$76,$A6,Casos!$M$2:$M$76,D$1) | E6: =COUNTIFS(Casos!$B$2:$B$76,$A6,Casos!$M$2:$M$76,E$1) | F6: =COUNTIFS(Casos!$B$2:$B$76,$A6,Casos!$M$2:$M$76,F$1) | G6: =COUNTIFS(Casos!$B$2:$B$76,$A6,Casos!$M$2:$M$76,G$1) | H6: =COUNTIFS(Casos!$B$2:$B$76,$A6,Casos!$M$2:$M$76,H$1) | I6: =COUNTIFS(Casos!$B$2:$B$76,$A6,Casos!$M$2:$M$76,I$1) | J6: =IF(C6=0,0,F6/C6)
A7: N5 | B7: No funcionales | C7: =COUNTIF(Casos!$B$2:$B$76,A7) | D7: =COUNTIFS(Casos!$B$2:$B$76,$A7,Casos!$M$2:$M$76,D$1) | E7: =COUNTIFS(Casos!$B$2:$B$76,$A7,Casos!$M$2:$M$76,E$1) | F7: =COUNTIFS(Casos!$B$2:$B$76,$A7,Casos!$M$2:$M$76,F$1) | G7: =COUNTIFS(Casos!$B$2:$B$76,$A7,Casos!$M$2:$M$76,G$1) | H7: =COUNTIFS(Casos!$B$2:$B$76,$A7,Casos!$M$2:$M$76,H$1) | I7: =COUNTIFS(Casos!$B$2:$B$76,$A7,Casos!$M$2:$M$76,I$1) | J7: =IF(C7=0,0,F7/C7)
A8: N6 | B8: Seguridad básica | C8: =COUNTIF(Casos!$B$2:$B$76,A8) | D8: =COUNTIFS(Casos!$B$2:$B$76,$A8,Casos!$M$2:$M$76,D$1) | E8: =COUNTIFS(Casos!$B$2:$B$76,$A8,Casos!$M$2:$M$76,E$1) | F8: =COUNTIFS(Casos!$B$2:$B$76,$A8,Casos!$M$2:$M$76,F$1) | G8: =COUNTIFS(Casos!$B$2:$B$76,$A8,Casos!$M$2:$M$76,G$1) | H8: =COUNTIFS(Casos!$B$2:$B$76,$A8,Casos!$M$2:$M$76,H$1) | I8: =COUNTIFS(Casos!$B$2:$B$76,$A8,Casos!$M$2:$M$76,I$1) | J8: =IF(C8=0,0,F8/C8)
A9: TOTAL | C9: =SUM(C2:C8) | D9: =SUM(D2:D8) | E9: =SUM(E2:E8) | F9: =SUM(F2:F8) | G9: =SUM(G2:G8) | H9: =SUM(H2:H8) | I9: =SUM(I2:I8) | J9: =IF(C9=0,0,F9/C9)

Sheet Trazabilidad
A1: Requisito | B1: Descripción | C1: N.º casos | D1: Casos
A2: RF-01 | B2: El sistema mide temperatura y humedad con el sensor conectado al ESP32. | C2: 4 | D2: IT-SEN-01, IT-SEN-03, IT-SEN-04, IT-SEN-05
A3: RF-02 | B3: El ESP32 se conecta a la red WiFi y recupera la conexión tras una caída. | C3: 3 | D3: IT-NET-01, IT-NET-02, IT-NET-03
A4: RF-03 | B4: El ESP32 envía cada lectura a la API en JSON, autenticado con API key. | C4: 2 | D4: IT-ENV-02, IT-API-18
A5: RF-04 | B5: La API valida el contenido y lo persiste en la base SQL. | C5: 12 | D5: IT-ENV-04, IT-API-01, IT-API-05, IT-API-07, IT-API-08, IT-API-10, IT-DB-01, IT-DB-05, IT-DB-06, IT-DB-07, IT-DB-10, IT-E2E-02
A6: RF-05 | B6: No se pierden ni se duplican lecturas ante reintentos, cortes o reinicios. | C6: 12 | D6: IT-SEN-02, IT-API-02, IT-API-12, IT-API-19, IT-API-20, IT-DB-02, IT-DB-03, IT-E2E-01, IT-E2E-03, IT-E2E-04, IT-NFR-02, IT-NFR-08
A7: RF-06 | B7: Las lecturas pueden consultarse por dispositivo y rango de tiempo. | C7: 3 | D7: IT-API-14, IT-API-15, IT-E2E-06
A8: RF-07 | B8: Se pueden agregar nuevas magnitudes (p. ej. PM2.5) sin cambiar el esquema. | C8: 2 | D8: IT-DB-04, IT-E2E-07
A9: RF-08 | B9: Un dashboard de Grafana muestra las lecturas almacenadas (temperatura, humedad, estado de los dispositivos). | C9: 1 | D9: IT-ENV-07
A10: RNF-01 | B10: Latencia de entrega (ESP32 → BD) con p95 menor a 2 s en condiciones normales. | C10: 3 | D10: IT-NFR-01, IT-NFR-03, IT-NFR-04
A11: RNF-02 | B11: El sistema se recupera solo tras caídas de red, API, BD o energía. | C11: 13 | D11: IT-ENV-01, IT-ENV-05, IT-ENV-06, IT-ENV-08, IT-NET-05, IT-API-17, IT-API-21, IT-DB-08, IT-DB-11, IT-NFR-05, IT-NFR-06, IT-NFR-07, IT-NFR-09
A12: RNF-03 | B12: Seguridad básica: autenticación, validación de entradas, BD no expuesta, sin secretos en el código. | C12: 16 | D12: IT-ENV-03, IT-API-03, IT-API-04, IT-API-06, IT-API-09, IT-API-13, IT-API-16, IT-SEC-01, IT-SEC-02, IT-SEC-03, IT-SEC-04, IT-SEC-05, IT-SEC-06, IT-SEC-07, IT-SEC-08, IT-SEC-09
A13: RNF-04 | B13: Trazabilidad temporal: cada lectura tiene hora del dispositivo (NTP) y hora del servidor. | C13: 4 | D13: IT-NET-04, IT-API-11, IT-DB-09, IT-E2E-05
